Workbook

Sheet Resumen
C1: usd PROMEDIO
A2: Efectivo | B2: 250000 | C2: 3850
A3: Cuenta Bancol | B3: 5019665
A4: pension voluntaria ahorro casa | B4: 102536491
A5: Investor trust 1200 | B5: =4855*C2 -> 18691750
A6: Investor trust 2400 | B6: =10280*C2 -> 39578000
A7: poliza pensiones skandia | B7: 12204069
A8: Fondo de emergencia lulo | B8: 585890
A9: Littio | B9: =56.6*C2 -> 217910
A10: Nequi | B10: 168222
A11: deuda | B11: =-6151674.16 -> -6151674.2
A12: Impuestos y Seguros Carro Moto
A13: NU (Viajes) | B13: 2619684
A19: TOTAL | B19: =SUM(B2:B18) -> 1.7572001e+08
A20: Diferencia | B20: =B19-GETPIVOTDATA("MONTO",$A$24) -> 2619684 | C20: =IF(B20=0,"Balanceado!", IF(B20<0,"Te falta $, ajusta!","Te sobra $, ajusta!")) -> Te sobra $, ajusta!
A24: Suma de MONTO | C24: MES
A25: CATEGORIA | B25: SUB CATEGORIA | C25: 1 A Limpiar | D25: A Ene | E25: B Feb | F25: C Mar | G25: D Abr | H25: E May | I25: F Jun | J25: G Jul | K25: H Ago | L25: I Sep | M25: J Oct | N25: K Nov | O25: L Dec | P25: Total
A26: AHORROS | B26: Fondo de Emergencia | D26: 0 | I26: 0 | J26: 0 | K26: 0 | L26: 0 | M26: 0 | N26: 0 | O26: 0 | P26: 0
B27: Efectivo | C27: 250000 | P27: 250000
B28: Cuenta Bancol | C28: 5019665 | P28: 5019665
B29: pension voluntaria ahorro casa | C29: 102536491 | P29: 102536491
B30: Investor trust 1200 | C30: 18691750 | P30: 18691750
B31: Investor trust 2400 | C31: 39578000 | P31: 39578000
B32: poliza pensiones skandia | C32: 12204069 | P32: 12204069
B33: Fondo de emergencia lulo | C33: 585890 | P33: 585890
B34: Litio | C34: 217910 | P34: 217910
B35: Nequi | C35: 168222 | P35: 168222
A36: AHORROS | C36: 179251997 | D36: 0 | I36: 0 | J36: 0 | K36: 0 | L36: 0 | M36: 0 | N36: 0 | O36: 0 | P36: 179251997
A38: REGALOS/ CARIDAD | B38: Regalos Navidad | C38: 0 | P38: 0
B39: Regalos cumpleaños | C39: 0 | P39: 0
A40: REGALOS/ CARIDAD | C40: 0 | P40: 0
A42: CASA | B42: Mantenimiento | C42: 0 | P42: 0
B43: Impuestos | C43: 0 | P43: 0
A44: CASA | C44: 0 | P44: 0
A46: SEGUROS | B46: Carro | C46: 0 | P46: 0
B47: Vida | C47: 0 | P47: 0
B48: Casa | C48: 0 | P48: 0
B49: Salud | C49: 0 | P49: 0
A50: SEGUROS | C50: 0 | P50: 0
A52: CUIDADO PERSONAL | B52: Ropa | C52: 0 | P52: 0
...

Sheet Plantilla Ppto
U1: =B13 -> Arriendo/Hipoteca
B2: PRESUPUESTO MENSUAL
B4: Ingreso Estimado | C4: Salario
C10: Total Ingreso Mensual | E10: =SUM(E4:E9) -> 0 | H10: Balance (Ingreso vs Presupuesto) | K10: =E10-SUM(D25,D36,D55,D65,D79,D88,D98,J25,J36,J55,J65,J88,J98,D108,J108,D46,J46,J79) -> 0 | M10: =IF(K10=0,"El presupuesto está listo","OJO! Tiene que sumar cero") -> El presupuesto está listo
B12: NECESIDADES BÁSICAS | C12: Ahorro | D12: Presupuesto | E12: Gasto | F12: Disponible | H12: AHORROS | I12: Ahorro | J12: Presupuesto | K12: Gasto | L12: Disponible
B13: Arriendo/Hipoteca | F13: =D13-E13 -> 0 | H13: Fondo de Emergencia | I13: SI | L13: =J13-K13 -> 0
B14: Telefono/ Celular | F14: =D14-E14 -> 0 | H14: Fondo de Pensión | I14: SI | L14: =J14-K14 -> 0
B15: Electricidad | F15: =D15-E15 -> 0 | H15: Fondo de Educación | I15: SI | L15: =J15-K15 -> 0
B16: Agua | F16: =D16-E16 -> 0 | H16: Cuota Inicial Casa | I16: SI | L16: =J16-K16 -> 0
B17: Gas | F17: =D17-E17 -> 0 | H17: Aporte a Capital | I17: SI | L17: =J17-K17 -> 0
B18: Cable/Internet | F18: =D18-E18 -> 0 | L18: =J18-K18 -> 0
B19: Super Mercado | F19: =D19-E19 -> 0 | L19: =J19-K19 -> 0
B20: Gasolina | F20: =D20-E20 -> 0 | L20: =J20-K20 -> 0
B21: Bus | F21: =D21-E21 -> 0 | L21: =J21-K21 -> 0
F22: =D22-E22 -> 0 | L22: =J22-K22 -> 0
F23: =D23-E23 -> 0 | L23: =J23-K23 -> 0
F24: =D24-E24 -> 0 | L24: =J24-K24 -> 0
B25: Subtotal | D25: =SUM(D13:D24) -> 0 | E25: =SUM(E13:E24) -> 0 | F25: =D25-E25 -> 0 | H25: Subtotal | J25: =SUM(J13:J24) -> 0 | K25: =SUM(K13:K24) -> 0 | L25: =J25-K25 -> 0
B27: DEUDAS | C27: Ahorro | D27: Presupuesto | E27: Gasto | F27: Disponible | H27: REGALOS/ CARIDAD | I27: Ahorro | J27: Presupuesto | K27: Gasto | L27: Disponible
B28: Deuda Carro | F28: =D28-E28 -> 0 | H28: Regalos Navidad | I28: SI | L28: =J28-K28 -> 0
B29: Deuda tarjeta 1 | F29: =D29-E29 -> 0 | H29: Regalos cumpleaños | I29: SI | L29: =J29-K29 -> 0
B30: Deuda tarjeta 2 | F30: =D30-E30 -> 0 | H30: Caridad | I30: SI | L30: =J30-K30 -> 0
B31: Deuda Estudio | F31: =D31-E31 -> 0 | L31: =J31-K31 -> 0
B32: Carro | F32: =D32-E32 -> 0 | L32: =J32-K32 -> 0
F33: =D33-E33 -> 0 | L33: =J33-K33 -> 0
F34: =D34-E34 -> 0 | L34: =J34-K34 -> 0
F35: =D35-E35 -> 0 | L35: =J35-K35 -> 0
B36: Subtotal | D36: =SUM(D28:D35) -> 0 | E36: =SUM(E28:E35) -> 0 | F36: =D36-E36 -> 0 | H36: Subtotal | J36: =SUM(J28:J35) -> 0 | K36: =SUM(K28:K35) -> 0 | L36: =J36-K36 -> 0
B38: CASA | C38: Ahorro | D38: Presupuesto | E38: Gasto | F38: Disponible | H38: TRANSPORTE | I38: Ahorro | J38: Presupuesto | K38: Gasto | L38: Disponible
B39: Limpieza | F39: =D39-E39 -> 0 | H39: Uber/taxi | L39: =J39-K39 -> 0
B40: Mantenimiento | F40: =D40-E40 -> 0 | H40: Estacionamiento | L40: =J40-K40 -> 0
B41: Muebles | F41: =D41-E41 -> 0 | H41: Mantenimiento | L41: =J41-K41 -> 0
B42: Impuestos | F42: =D42-E42 -> 0 | H42: Impuestos | L42: =J42-K42 -> 0
F43: =D43-E43 -> 0 | H43: Panapass/Peaje | L43: =J43-K43 -> 0
F44: =D44-E44 -> 0 | L44: =J44-K44 -> 0
F45: =D45-E45 -> 0 | L45: =J45-K45 -> 0
B46: Subtotal | D46: =SUM(D39:D45) -> 0 | E46: =SUM(E39:E45) -> 0 | F46: =D46-E46 -> 0 | H46: Subtotal | J46: =SUM(J39:J45) -> 0 | K46: =SUM(K39:K45) -> 0 | L46: =J46-K46 -> 0
B48: ALIMENTACIÓN | C48: Ahorro | D48: Presupuesto | E48: Gasto | F48: Disponible | H48: SEGUROS | I48: Ahorro | J48: Presupuesto | K48: Gasto | L48: Disponible
B49: Restaurantes | F49: =D49-E49 -> 0 | H49: Carro | L49: =J49-K49 -> 0
B50: Café/ Snacks | F50: =D50-E50 -> 0 | H50: Vida | L50: =J50-K50 -> 0
...

Sheet Para proyectar
U1: =B13 -> Arriendo/Hipoteca
B2: PRESUPUESTO MENSUAL
B4: Ingreso Estimado | C4: Salario | E4: 9714500
C5: saldo mes anterior
C6: Efectivo
C7: nequi
C10: Total Ingreso Mensual | E10: =SUM(E4:E9) -> 9714500 | H10: Balance (Ingreso vs Presupuesto) | K10: =E10-SUM(D25,D36,D55,D65,D79,D88,D98,J25,J36,J55,J65,J88,J98,D108,J108,D46,J46,J79) -> 956 | M10: =IF(K10=0,"El presupuesto está listo","OJO! Tiene que sumar cero") -> OJO! Tiene que sumar cero
B12: NECESIDADES BÁSICAS | C12: Ahorro | D12: Presupuesto | E12: Gasto | F12: Disponible | H12: AHORROS | I12: Ahorro | J12: Presupuesto | K12: Gasto | L12: Disponible
B13: Arriendo/Hipoteca | D13: 2000000 | E13: =SUMIFS('Enero - registro gastos'!$D$3:$D$300,'Enero - registro gastos'!$E$3:$E$300,Ene!$B$12,'Enero - registro gastos'!$F$3:$F$300,Ene!B13) -> 0 | F13: =D13-E13 -> 2000000 | H13: Efectivo | I13: SI | K13: =SUMIFS('Enero - registro gastos'!$D$3:$D$300,'Enero - registro gastos'!$E$3:$E$300,Ene!$H$12,'Enero - registro gastos'!$F$3:$F$300,Ene!H13) -> 0 | L13: =J13-K13 -> 0
B14: Telefono/ Celular | D14: 78000 | E14: =SUMIFS('Enero - registro gastos'!$D$3:$D$300,'Enero - registro gastos'!$E$3:$E$300,Ene!$B$12,'Enero - registro gastos'!$F$3:$F$300,Ene!B14) -> 77988 | F14: =D14-E14 -> 12 | H14: Cuenta Bancol | I14: SI | K14: =SUMIFS('Enero - registro gastos'!$D$3:$D$300,'Enero - registro gastos'!$E$3:$E$300,Ene!$H$12,'Enero - registro gastos'!$F$3:$F$300,Ene!H14) -> 0 | L14: =J14-K14 -> 0
B15: Electricidad | D15: 50000 | E15: =SUMIFS('Enero - registro gastos'!$D$3:$D$300,'Enero - registro gastos'!$E$3:$E$300,Ene!$B$12,'Enero - registro gastos'!$F$3:$F$300,Ene!B15) -> 0 | F15: =D15-E15 -> 50000 | H15: pension voluntaria ahorro casa | I15: SI | J15: =100000+1250000 -> 1350000 | K15: =SUMIFS('Enero - registro gastos'!$D$3:$D$300,'Enero - registro gastos'!$E$3:$E$300,Ene!$H$12,'Enero - registro gastos'!$F$3:$F$300,Ene!H15) -> 0 | L15: =J15-K15 -> 1350000
B16: Agua | D16: 50000 | E16: =SUMIFS('Enero - registro gastos'!$D$3:$D$300,'Enero - registro gastos'!$E$3:$E$300,Ene!$B$12,'Enero - registro gastos'!$F$3:$F$300,Ene!B16) -> 0 | F16: =D16-E16 -> 50000 | H16: Investor trust 1200 | I16: SI | J16: =100*Resumen!C2 -> 385000 | K16: =SUMIFS('Enero - registro gastos'!$D$3:$D$300,'Enero - registro gastos'!$E$3:$E$300,Ene!$H$12,'Enero - registro gastos'!$F$3:$F$300,Ene!H16) -> 0 | L16: =J16-K16 -> 385000
B17: Gas | D17: 15000 | E17: =SUMIFS('Enero - registro gastos'!$D$3:$D$300,'Enero - registro gastos'!$E$3:$E$300,Ene!$B$12,'Enero - registro gastos'!$F$3:$F$300,Ene!B17) -> 0 | F17: =D17-E17 -> 15000 | H17: Investor trust 2400 | I17: SI | J17: =200*Resumen!C2 -> 770000 | K17: =SUMIFS('Enero - registro gastos'!$D$3:$D$300,'Enero - registro gastos'!$E$3:$E$300,Ene!$H$12,'Enero - registro gastos'!$F$3:$F$300,Ene!H17) -> 0 | L17: =J17-K17 -> 770000
B18: Cable/Internet | D18: 140000 | E18: =SUMIFS('Enero - registro gastos'!$D$3:$D$300,'Enero - registro gastos'!$E$3:$E$300,Ene!$B$12,'Enero - registro gastos'!$F$3:$F$300,Ene!B18) -> 142988 | F18: =D18-E18 -> -2988 | H18: poliza pensiones skandia | I18: SI | J18: 336000 | K18: =SUMIFS('Enero - registro gastos'!$D$3:$D$300,'Enero - registro gastos'!$E$3:$E$300,Ene!$H$12,'Enero - registro gastos'!$F$3:$F$300,Ene!H18) -> 0 | L18: =J18-K18 -> 336000
B19: Super Mercado | D19: 300000 | E19: =SUMIFS('Enero - registro gastos'!$D$3:$D$300,'Enero - registro gastos'!$E$3:$E$300,Ene!$B$12,'Enero - registro gastos'!$F$3:$F$300,Ene!B19) -> 0 | F19: =D19-E19 -> 300000 | H19: Fondo de emergencia lulo | I19: SI | J19: 200000 | K19: =SUMIFS('Enero - registro gastos'!$D$3:$D$300,'Enero - registro gastos'!$E$3:$E$300,Ene!$H$12,'Enero - registro gastos'!$F$3:$F$300,Ene!H19) -> 0 | L19: =J19-K19 -> 200000
B20: Gasolina | D20: 200000 | E20: =SUMIFS('Enero - registro gastos'!$D$3:$D$300,'Enero - registro gastos'!$E$3:$E$300,Ene!$B$12,'Enero - registro gastos'!$F$3:$F$300,Ene!B20) -> 0 | F20: =D20-E20 -> 200000 | H20: Littio | I20: SI | J20: 500000 | K20: =SUMIFS('Enero - registro gastos'!$D$3:$D$300,'Enero - registro gastos'!$E$3:$E$300,Ene!$H$12,'Enero - registro gastos'!$F$3:$F$300,Ene!H20) -> 0 | L20: =J20-K20 -> 500000
B21: Bus | E21: =SUMIFS('Enero - registro gastos'!$D$3:$D$300,'Enero - registro gastos'!$E$3:$E$300,Ene!$B$12,'Enero - registro gastos'!$F$3:$F$300,Ene!B21) -> 0 | F21: =D21-E21 -> 0 | H21: Nequi | I21: SI | J21: 500000 | K21: =SUMIFS('Enero - registro gastos'!$D$3:$D$300,'Enero - registro gastos'!$E$3:$E$300,Ene!$H$12,'Enero - registro gastos'!$F$3:$F$300,Ene!H21) -> 0 | L21: =J21-K21 -> 500000
E22: =SUMIFS('Enero - registro gastos'!$D$3:$D$300,'Enero - registro gastos'!$E$3:$E$300,Ene!$B$12,'Enero - registro gastos'!$F$3:$F$300,Ene!B22) -> 0 | F22: =D22-E22 -> 0 | H22: viajes varios | I22: SI | K22: =SUMIFS('Enero - registro gastos'!$D$3:$D$300,'Enero - registro gastos'!$E$3:$E$300,Ene!$H$12,'Enero - registro gastos'!$F$3:$F$300,Ene!H22) -> 0 | L22: =J22-K22 -> 0
E23: =SUMIFS('Enero - registro gastos'!$D$3:$D$300,'Enero - registro gastos'!$E$3:$E$300,Ene!$B$12,'Enero - registro gastos'!$F$3:$F$300,Ene!B23) -> 0 | F23: =D23-E23 -> 0 | H23: Viaje Japon | I23: SI | J23: 1000000 | K23: =SUMIFS('Enero - registro gastos'!$D$3:$D$300,'Enero - registro gastos'!$E$3:$E$300,Ene!$H$12,'Enero - registro gastos'!$F$3:$F$300,Ene!H23) -> 0 | L23: =J23-K23 -> 1000000
E24: =SUMIFS('Enero - registro gastos'!$D$3:$D$300,'Enero - registro gastos'!$E$3:$E$300,Ene!$B$12,'Enero - registro gastos'!$F$3:$F$300,Ene!B24) -> 0 | F24: =D24-E24 -> 0 | K24: =SUMIFS('Enero - registro gastos'!$D$3:$D$300,'Enero - registro gastos'!$E$3:$E$300,Ene!$H$12,'Enero - registro gastos'!$F$3:$F$300,Ene!H24) -> 0 | L24: =J24-K24 -> 0
B25: Subtotal | D25: =SUM(D13:D24) -> 2833000 | E25: =SUM(E13:E24) -> 220976 | F25: =D25-E25 -> 2612024 | H25: Subtotal | J25: =SUM(J13:J24) -> 5041000 | K25: =SUM(K13:K24) -> 0 | L25: =J25-K25 -> 5041000
B27: DEUDAS | C27: Ahorro | D27: Presupuesto | E27: Gasto | F27: Disponible | H27: REGALOS/ CARIDAD | I27: Ahorro | J27: Presupuesto | K27: Gasto | L27: Disponible
B28: Deuda Carro | E28: =SUMIFS('Enero - registro gastos'!$D$3:$D$300,'Enero - registro gastos'!$E$3:$E$300,Ene!$B$27,'Enero - registro gastos'!$F$3:$F$300,Ene!B28) -> 0 | F28: =D28-E28 -> 0 | H28: Regalos Navidad | K28: =SUMIFS('Enero - registro gastos'!$D$3:$D$300,'Enero - registro gastos'!$E$3:$E$300,Ene!$H$27,'Enero - registro gastos'!$F$3:$F$300,Ene!H28) -> 0 | L28: =J28-K28 -> 0
B29: Deuda tarjeta Un | E29: =SUMIFS('Enero - registro gastos'!$D$3:$D$300,'Enero - registro gastos'!$E$3:$E$300,Ene!$B$27,'Enero - registro gastos'!$F$3:$F$300,Ene!B29) -> 3917064.8 | F29: =D29-E29 -> -3917064.8 | H29: Regalos cumpleaños | J29: 150000 | K29: =SUMIFS('Enero - registro gastos'!$D$3:$D$300,'Enero - registro gastos'!$E$3:$E$300,Ene!$H$27,'Enero - registro gastos'!$F$3:$F$300,Ene!H29) -> 0 | L29: =J29-K29 -> 150000
B30: Deuda Banco de occidente | E30: =SUMIFS('Enero - registro gastos'!$D$3:$D$300,'Enero - registro gastos'!$E$3:$E$300,Ene!$B$27,'Enero - registro gastos'!$F$3:$F$300,Ene!B30) -> 0 | F30: =D30-E30 -> 0 | H30: Caridad | J30: 55000 | K30: =SUMIFS('Enero - registro gastos'!$D$3:$D$300,'Enero - registro gastos'!$E$3:$E$300,Ene!$H$27,'Enero - registro gastos'!$F$3:$F$300,Ene!H30) -> 55000 | L30: =J30-K30 -> 0
B31: Deuda Estudio | E31: =SUMIFS('Enero - registro gastos'!$D$3:$D$300,'Enero - registro gastos'!$E$3:$E$300,Ene!$B$27,'Enero - registro gastos'!$F$3:$F$300,Ene!B31) -> 0 | F31: =D31-E31 -> 0 | K31: =SUMIFS('Enero - registro gastos'!$D$3:$D$300,'Enero - registro gastos'!$E$3:$E$300,Ene!$H$27,'Enero - registro gastos'!$F$3:$F$300,Ene!H31) -> 0 | L31: =J31-K31 -> 0
B32: Carro | E32: =SUMIFS('Enero - registro gastos'!$D$3:$D$300,'Enero - registro gastos'!$E$3:$E$300,Ene!$B$27,'Enero - registro gastos'!$F$3:$F$300,Ene!B32) -> 0 | F32: =D32-E32 -> 0 | K32: =SUMIFS('Enero - registro gastos'!$D$3:$D$300,'Enero - registro gastos'!$E$3:$E$300,Ene!$H$27,'Enero - registro gastos'!$F$3:$F$300,Ene!H32) -> 0 | L32: =J32-K32 -> 0
E33: =SUMIFS('Enero - registro gastos'!$D$3:$D$300,'Enero - registro gastos'!$E$3:$E$300,Ene!$B$27,'Enero - registro gastos'!$F$3:$F$300,Ene!B33) -> 0 | F33: =D33-E33 -> 0 | K33: =SUMIFS('Enero - registro gastos'!$D$3:$D$300,'Enero - registro gastos'!$E$3:$E$300,Ene!$H$27,'Enero - registro gastos'!$F$3:$F$300,Ene!H33) -> 0 | L33: =J33-K33 -> 0
E34: =SUMIFS('Enero - registro gastos'!$D$3:$D$300,'Enero - registro gastos'!$E$3:$E$300,Ene!$B$27,'Enero - registro gastos'!$F$3:$F$300,Ene!B34) -> 0 | F34: =D34-E34 -> 0 | K34: =SUMIFS('Enero - registro gastos'!$D$3:$D$300,'Enero - registro gastos'!$E$3:$E$300,Ene!$H$27,'Enero - registro gastos'!$F$3:$F$300,Ene!H34) -> 0 | L34: =J34-K34 -> 0
E35: =SUMIFS('Enero - registro gastos'!$D$3:$D$300,'Enero - registro gastos'!$E$3:$E$300,Ene!$B$27,'Enero - registro gastos'!$F$3:$F$300,Ene!B35) -> 0 | F35: =D35-E35 -> 0 | K35: =SUMIFS('Enero - registro gastos'!$D$3:$D$300,'Enero - registro gastos'!$E$3:$E$300,Ene!$H$27,'Enero - registro gastos'!$F$3:$F$300,Ene!H35) -> 0 | L35: =J35-K35 -> 0
B36: Subtotal | D36: =SUM(D28:D35) -> 0 | E36: =SUM(E28:E35) -> 3917064.8 | F36: =D36-E36 -> -3917064.8 | H36: Subtotal | J36: =SUM(J28:J35) -> 205000 | K36: =SUM(K28:K35) -> 55000 | L36: =J36-K36 -> 150000
B38: CASA | C38: Ahorro | D38: Presupuesto | E38: Gasto | F38: Disponible | H38: TRANSPORTE | I38: Ahorro | J38: Presupuesto | K38: Gasto | L38: Disponible
B39: Limpieza | E39: =SUMIFS('Enero - registro gastos'!$D$3:$D$300,'Enero - registro gastos'!$E$3:$E$300,Ene!$B$38,'Enero - registro gastos'!$F$3:$F$300,Ene!B39) -> 0 | F39: =D39-E39 -> 0 | H39: Uber/taxi | J39: 95000 | K39: =SUMIFS('Enero - registro gastos'!$D$3:$D$300,'Enero - registro gastos'!$E$3:$E$300,Ene!$H$38,'Enero - registro gastos'!$F$3:$F$300,Ene!H39) -> 0 | L39: =J39-K39 -> 95000
B40: Mantenimiento | E40: =SUMIFS('Enero - registro gastos'!$D$3:$D$300,'Enero - registro gastos'!$E$3:$E$300,Ene!$B$38,'Enero - registro gastos'!$F$3:$F$300,Ene!B40) -> 0 | F40: =D40-E40 -> 0 | H40: Estacionamiento | K40: =SUMIFS('Enero - registro gastos'!$D$3:$D$300,'Enero - registro gastos'!$E$3:$E$300,Ene!$H$38,'Enero - registro gastos'!$F$3:$F$300,Ene!H40) -> 0 | L40: =J40-K40 -> 0
B41: Muebles | E41: =SUMIFS('Enero - registro gastos'!$D$3:$D$300,'Enero - registro gastos'!$E$3:$E$300,Ene!$B$38,'Enero - registro gastos'!$F$3:$F$300,Ene!B41) -> 0 | F41: =D41-E41 -> 0 | H41: Mantenimiento | K41: =SUMIFS('Enero - registro gastos'!$D$3:$D$300,'Enero - registro gastos'!$E$3:$E$300,Ene!$H$38,'Enero - registro gastos'!$F$3:$F$300,Ene!H41) -> 0 | L41: =J41-K41 -> 0
B42: Impuestos | E42: =SUMIFS('Enero - registro gastos'!$D$3:$D$300,'Enero - registro gastos'!$E$3:$E$300,Ene!$B$38,'Enero - registro gastos'!$F$3:$F$300,Ene!B42) -> 0 | F42: =D42-E42 -> 0 | H42: Impuestos | K42: =SUMIFS('Enero - registro gastos'!$D$3:$D$300,'Enero - registro gastos'!$E$3:$E$300,Ene!$H$38,'Enero - registro gastos'!$F$3:$F$300,Ene!H42) -> 0 | L42: =J42-K42 -> 0
E43: =SUMIFS('Enero - registro gastos'!$D$3:$D$300,'Enero - registro gastos'!$E$3:$E$300,Ene!$B$38,'Enero - registro gastos'!$F$3:$F$300,Ene!B43) -> 0 | F43: =D43-E43 -> 0 | H43: Panapass/Peaje | J43: 20000 | K43: =SUMIFS('Enero - registro gastos'!$D$3:$D$300,'Enero - registro gastos'!$E$3:$E$300,Ene!$H$38,'Enero - registro gastos'!$F$3:$F$300,Ene!H43) -> 0 | L43: =J43-K43 -> 20000
E44: =SUMIFS('Enero - registro gastos'!$D$3:$D$300,'Enero - registro gastos'!$E$3:$E$300,Ene!$B$38,'Enero - registro gastos'!$F$3:$F$300,Ene!B44) -> 0 | F44: =D44-E44 -> 0 | K44: =SUMIFS('Enero - registro gastos'!$D$3:$D$300,'Enero - registro gastos'!$E$3:$E$300,Ene!$H$38,'Enero - registro gastos'!$F$3:$F$300,Ene!H44) -> 0 | L44: =J44-K44 -> 0
E45: =SUMIFS('Enero - registro gastos'!$D$3:$D$300,'Enero - registro gastos'!$E$3:$E$300,Ene!$B$38,'Enero - registro gastos'!$F$3:$F$300,Ene!B45) -> 0 | F45: =D45-E45 -> 0 | K45: =SUMIFS('Enero - registro gastos'!$D$3:$D$300,'Enero - registro gastos'!$E$3:$E$300,Ene!$H$38,'Enero - registro gastos'!$F$3:$F$300,Ene!H45) -> 0 | L45: =J45-K45 -> 0
B46: Subtotal | D46: =SUM(D39:D45) -> 0 | E46: =SUM(E39:E45) -> 0 | F46: =D46-E46 -> 0 | H46: Subtotal | J46: =SUM(J39:J45) -> 115000 | K46: =SUM(K39:K45) -> 0 | L46: =J46-K46 -> 115000
...

Sheet Limpieza
U1: =B13 -> Arriendo/Hipoteca
B2: PRESUPUESTO MENSUAL
B4: Ingreso Estimado | E4: =185403671+2619683.99 -> 1.8802335e+08
C10: Total Ingreso Mensual | E10: =SUM(E4:E9) -> 1.8802335e+08 | H10: Balance (Ingreso vs Presupuesto) | K10: =E10-SUM(D25,D36,D55,D65,D79,D88,D98,J25,J36,J55,J65,J88,J98,D108,J108,D46,J46,J79) -> 6151674 | M10: =IF(K10=0,"El presupuesto está listo","OJO! Tiene que sumar cero") -> OJO! Tiene que sumar cero
B12: NECESIDADES BÁSICAS | C12: Ahorro | D12: Presupuesto | E12: Gasto | F12: Disponible | H12: AHORROS | I12: Ahorro | J12: Presupuesto | K12: Gasto | L12: Disponible
B13: Arriendo/Hipoteca | F13: =D13-E13 -> 0 | H13: Efectivo | I13: SI | J13: 250000 | L13: =J13-K13 -> 250000
B14: Telefono/ Celular | F14: =D14-E14 -> 0 | H14: Cuenta Bancol | I14: SI | J14: 5019665 | L14: =J14-K14 -> 5019665
B15: Electricidad | F15: =D15-E15 -> 0 | H15: pension voluntaria ahorro casa | I15: SI | J15: 102536491 | L15: =J15-K15 -> 102536491
B16: Agua | F16: =D16-E16 -> 0 | H16: Investor trust 1200 | I16: SI | J16: 18691750 | L16: =J16-K16 -> 18691750
B17: Gas | F17: =D17-E17 -> 0 | H17: Investor trust 2400 | I17: SI | J17: 39578000 | L17: =J17-K17 -> 39578000
B18: Cable/Internet | F18: =D18-E18 -> 0 | H18: poliza pensiones skandia | I18: SI | J18: 12204069 | L18: =J18-K18 -> 12204069
B19: Super Mercado | F19: =D19-E19 -> 0 | H19: Fondo de emergencia lulo | I19: SI | J19: 585890 | L19: =J19-K19 -> 585890
B20: Gasolina | F20: =D20-E20 -> 0 | H20: Littio | I20: SI | J20: 217910 | L20: =J20-K20 -> 217910
B21: Bus | F21: =D21-E21 -> 0 | H21: Nequi | I21: SI | J21: 168222 | L21: =J21-K21 -> 168222
F22: =D22-E22 -> 0 | H22: NU (viajes) | I22: SI | J22: 2619684 | L22: =J22-K22 -> 2619684
F23: =D23-E23 -> 0 | L23: =J23-K23 -> 0
F24: =D24-E24 -> 0 | L24: =J24-K24 -> 0
B25: Subtotal | D25: =SUM(D13:D24) -> 0 | E25: =SUM(E13:E24) -> 0 | F25: =D25-E25 -> 0 | H25: Subtotal | J25: =SUM(J13:J24) -> 1.8187168e+08 | K25: =SUM(K13:K24) -> 0 | L25: =J25-K25 -> 1.8187168e+08
B27: DEUDAS | C27: Ahorro | D27: Presupuesto | E27: Gasto | F27: Disponible | H27: REGALOS/ CARIDAD | I27: Ahorro | J27: Presupuesto | K27: Gasto | L27: Disponible
B28: Deuda Carro | F28: =D28-E28 -> 0 | H28: Regalos Navidad | I28: SI | L28: =J28-K28 -> 0
B29: Deuda tarjeta Nu | C29: SI | E29: 6151674.2 | F29: =D29-E29 -> -6151674.2 | H29: Regalos cumpleaños | I29: SI | L29: =J29-K29 -> 0
B30: Deuda tarjeta 2 | F30: =D30-E30 -> 0 | H30: Caridad | L30: =J30-K30 -> 0
B31: Deuda Estudio | F31: =D31-E31 -> 0 | L31: =J31-K31 -> 0
B32: Carro | F32: =D32-E32 -> 0 | L32: =J32-K32 -> 0
F33: =D33-E33 -> 0 | L33: =J33-K33 -> 0
F34: =D34-E34 -> 0 | L34: =J34-K34 -> 0
F35: =D35-E35 -> 0 | L35: =J35-K35 -> 0
B36: Subtotal | D36: =SUM(D28:D35) -> 0 | E36: =SUM(E28:E35) -> 6151674.2 | F36: =D36-E36 -> -6151674.2 | H36: Subtotal | J36: =SUM(J28:J35) -> 0 | K36: =SUM(K28:K35) -> 0 | L36: =J36-K36 -> 0
B38: CASA | C38: Ahorro | D38: Presupuesto | E38: Gasto | F38: Disponible | H38: TRANSPORTE | I38: Ahorro | J38: Presupuesto | K38: Gasto | L38: Disponible
B39: Limpieza | F39: =D39-E39 -> 0 | H39: Uber/taxi | L39: =J39-K39 -> 0
B40: Mantenimiento | C40: SI | F40: =D40-E40 -> 0 | H40: Estacionamiento | L40: =J40-K40 -> 0
B41: Muebles | F41: =D41-E41 -> 0 | H41: Mantenimiento | I41: SI | L41: =J41-K41 -> 0
B42: Impuestos | C42: SI | F42: =D42-E42 -> 0 | H42: Impuestos | I42: SI | L42: =J42-K42 -> 0
F43: =D43-E43 -> 0 | H43: Panapass/Peaje | L43: =J43-K43 -> 0
F44: =D44-E44 -> 0 | L44: =J44-K44 -> 0
F45: =D45-E45 -> 0 | L45: =J45-K45 -> 0
B46: Subtotal | D46: =SUM(D39:D45) -> 0 | E46: =SUM(E39:E45) -> 0 | F46: =D46-E46 -> 0 | H46: Subtotal | J46: =SUM(J39:J45) -> 0 | K46: =SUM(K39:K45) -> 0 | L46: =J46-K46 -> 0
B48: ALIMENTACIÓN | C48: Ahorro | D48: Presupuesto | E48: Gasto | F48: Disponible | H48: SEGUROS | I48: Ahorro | J48: Presupuesto | K48: Gasto | L48: Disponible
B49: Restaurantes | F49: =D49-E49 -> 0 | H49: Carro | I49: SI | L49: =J49-K49 -> 0
B50: Café/ Snacks | F50: =D50-E50 -> 0 | H50: Vida | I50: SI | L50: =J50-K50 -> 0
...

Sheet Ene
U1: =B13 -> Arriendo/Hipoteca
B2: PRESUPUESTO MENSUAL
B4: Ingreso Estimado | C4: Salario | E4: 9714500
C5: saldo mes anterior | E5: 5074509 | H5: lulo 2531710
C6: Efectivo | E6: 100000
C7: nequi | E7: 100000
C8: Pago Tita | E8: 400000
C10: Total Ingreso Mensual | E10: =SUM(E4:E9) -> 15389009 | H10: Balance (Ingreso vs Presupuesto) | K10: =E10-SUM(D25,D36,D55,D65,D79,D88,D98,J25,J36,J55,J65,J88,J98,D108,J108,D46,J46,J79) -> 0 | M10: =IF(K10=0,"El presupuesto está listo","OJO! Tiene que sumar cero") -> El presupuesto está listo
B12: NECESIDADES BÁSICAS | C12: Ahorro | D12: Presupuesto | E12: Gasto | F12: Disponible | H12: AHORROS | I12: Ahorro | J12: Presupuesto | K12: Gasto | L12: Disponible
B13: Arriendo/Hipoteca | E13: =SUMIFS('Enero - registro gastos'!$D$3:$D$300,'Enero - registro gastos'!$E$3:$E$300,Ene!$B$12,'Enero - registro gastos'!$F$3:$F$300,Ene!B13) -> 0 | F13: =D13-E13 -> 0 | H13: Efectivo | I13: SI | J13: 400000 | K13: =SUMIFS('Enero - registro gastos'!$D$3:$D$300,'Enero - registro gastos'!$E$3:$E$300,Ene!$H$12,'Enero - registro gastos'!$F$3:$F$300,Ene!H13) -> 0 | L13: =J13-K13 -> 400000
B14: Telefono/ Celular | D14: 78000 | E14: =SUMIFS('Enero - registro gastos'!$D$3:$D$300,'Enero - registro gastos'!$E$3:$E$300,Ene!$B$12,'Enero - registro gastos'!$F$3:$F$300,Ene!B14) -> 77988 | F14: =D14-E14 -> 12 | H14: Cuenta Bancol | I14: SI | K14: =SUMIFS('Enero - registro gastos'!$D$3:$D$300,'Enero - registro gastos'!$E$3:$E$300,Ene!$H$12,'Enero - registro gastos'!$F$3:$F$300,Ene!H14) -> 0 | L14: =J14-K14 -> 0
B15: Electricidad | E15: =SUMIFS('Enero - registro gastos'!$D$3:$D$300,'Enero - registro gastos'!$E$3:$E$300,Ene!$B$12,'Enero - registro gastos'!$F$3:$F$300,Ene!B15) -> 0 | F15: =D15-E15 -> 0 | H15: pension voluntaria ahorro casa | I15: SI | J15: =100000+1750000 -> 1850000 | K15: =SUMIFS('Enero - registro gastos'!$D$3:$D$300,'Enero - registro gastos'!$E$3:$E$300,Ene!$H$12,'Enero - registro gastos'!$F$3:$F$300,Ene!H15) -> 0 | L15: =J15-K15 -> 1850000
B16: Agua | E16: =SUMIFS('Enero - registro gastos'!$D$3:$D$300,'Enero - registro gastos'!$E$3:$E$300,Ene!$B$12,'Enero - registro gastos'!$F$3:$F$300,Ene!B16) -> 0 | F16: =D16-E16 -> 0 | H16: Investor trust 1200 | I16: SI | J16: =100*Resumen!C2 -> 385000 | K16: =SUMIFS('Enero - registro gastos'!$D$3:$D$300,'Enero - registro gastos'!$E$3:$E$300,Ene!$H$12,'Enero - registro gastos'!$F$3:$F$300,Ene!H16) -> 0 | L16: =J16-K16 -> 385000
B17: Gas | D17: 15000 | E17: =SUMIFS('Enero - registro gastos'!$D$3:$D$300,'Enero - registro gastos'!$E$3:$E$300,Ene!$B$12,'Enero - registro gastos'!$F$3:$F$300,Ene!B17) -> 0 | F17: =D17-E17 -> 15000 | H17: Investor trust 2400 | I17: SI | J17: =200*Resumen!C2 -> 770000 | K17: =SUMIFS('Enero - registro gastos'!$D$3:$D$300,'Enero - registro gastos'!$E$3:$E$300,Ene!$H$12,'Enero - registro gastos'!$F$3:$F$300,Ene!H17) -> 0 | L17: =J17-K17 -> 770000
B18: Cable/Internet | D18: 140000 | E18: =SUMIFS('Enero - registro gastos'!$D$3:$D$300,'Enero - registro gastos'!$E$3:$E$300,Ene!$B$12,'Enero - registro gastos'!$F$3:$F$300,Ene!B18) -> 142988 | F18: =D18-E18 -> -2988 | H18: poliza pensiones skandia | I18: SI | J18: 336000 | K18: =SUMIFS('Enero - registro gastos'!$D$3:$D$300,'Enero - registro gastos'!$E$3:$E$300,Ene!$H$12,'Enero - registro gastos'!$F$3:$F$300,Ene!H18) -> 0 | L18: =J18-K18 -> 336000
B19: Super Mercado | D19: 300000 | E19: =SUMIFS('Enero - registro gastos'!$D$3:$D$300,'Enero - registro gastos'!$E$3:$E$300,Ene!$B$12,'Enero - registro gastos'!$F$3:$F$300,Ene!B19) -> 0 | F19: =D19-E19 -> 300000 | H19: Fondo de emergencia lulo | I19: SI | J19: 0 | K19: =SUMIFS('Enero - registro gastos'!$D$3:$D$300,'Enero - registro gastos'!$E$3:$E$300,Ene!$H$12,'Enero - registro gastos'!$F$3:$F$300,Ene!H19) -> 0 | L19: =J19-K19 -> 0
B20: Gasolina | D20: 200000 | E20: =SUMIFS('Enero - registro gastos'!$D$3:$D$300,'Enero - registro gastos'!$E$3:$E$300,Ene!$B$12,'Enero - registro gastos'!$F$3:$F$300,Ene!B20) -> 0 | F20: =D20-E20 -> 200000 | H20: Littio | I20: SI | J20: 100000 | K20: =SUMIFS('Enero - registro gastos'!$D$3:$D$300,'Enero - registro gastos'!$E$3:$E$300,Ene!$H$12,'Enero - registro gastos'!$F$3:$F$300,Ene!H20) -> 0 | L20: =J20-K20 -> 100000
B21: Bus | E21: =SUMIFS('Enero - registro gastos'!$D$3:$D$300,'Enero - registro gastos'!$E$3:$E$300,Ene!$B$12,'Enero - registro gastos'!$F$3:$F$300,Ene!B21) -> 0 | F21: =D21-E21 -> 0 | H21: Nequi | I21: SI | K21: =SUMIFS('Enero - registro gastos'!$D$3:$D$300,'Enero - registro gastos'!$E$3:$E$300,Ene!$H$12,'Enero - registro gastos'!$F$3:$F$300,Ene!H21) -> 0 | L21: =J21-K21 -> 0
E22: =SUMIFS('Enero - registro gastos'!$D$3:$D$300,'Enero - registro gastos'!$E$3:$E$300,Ene!$B$12,'Enero - registro gastos'!$F$3:$F$300,Ene!B22) -> 0 | F22: =D22-E22 -> 0 | H22: viajes varios | I22: SI | J22: 300000 | K22: =SUMIFS('Enero - registro gastos'!$D$3:$D$300,'Enero - registro gastos'!$E$3:$E$300,Ene!$H$12,'Enero - registro gastos'!$F$3:$F$300,Ene!H22) -> 0 | L22: =J22-K22 -> 300000
E23: =SUMIFS('Enero - registro gastos'!$D$3:$D$300,'Enero - registro gastos'!$E$3:$E$300,Ene!$B$12,'Enero - registro gastos'!$F$3:$F$300,Ene!B23) -> 0 | F23: =D23-E23 -> 0 | H23: Viaje Japon lulo | I23: SI | J23: 1331710 | K23: =SUMIFS('Enero - registro gastos'!$D$3:$D$300,'Enero - registro gastos'!$E$3:$E$300,Ene!$H$12,'Enero - registro gastos'!$F$3:$F$300,Ene!H23) -> 0 | L23: =J23-K23 -> 1331710
E24: =SUMIFS('Enero - registro gastos'!$D$3:$D$300,'Enero - registro gastos'!$E$3:$E$300,Ene!$B$12,'Enero - registro gastos'!$F$3:$F$300,Ene!B24) -> 0 | F24: =D24-E24 -> 0 | H24: Viaje Estados unidos lulo | I24: SI | J24: =1727928 -> 1727928 | K24: =SUMIFS('Enero - registro gastos'!$D$3:$D$300,'Enero - registro gastos'!$E$3:$E$300,Ene!$H$12,'Enero - registro gastos'!$F$3:$F$300,Ene!H24) -> 0 | L24: =J24-K24 -> 1727928
B25: Subtotal | D25: =SUM(D13:D24) -> 733000 | E25: =SUM(E13:E24) -> 220976 | F25: =D25-E25 -> 512024 | H25: Subtotal | J25: =SUM(J13:J24) -> 7200638 | K25: =SUM(K13:K24) -> 0 | L25: =J25-K25 -> 7200638
B27: DEUDAS | C27: Ahorro | D27: Presupuesto | E27: Gasto | F27: Disponible | H27: REGALOS/ CARIDAD | I27: Ahorro | J27: Presupuesto | K27: Gasto | L27: Disponible
B28: Deuda Carro | E28: =SUMIFS('Enero - registro gastos'!$D$3:$D$300,'Enero - registro gastos'!$E$3:$E$300,Ene!$B$27,'Enero - registro gastos'!$F$3:$F$300,Ene!B28) -> 0 | F28: =D28-E28 -> 0 | H28: Regalos Navidad | K28: =SUMIFS('Enero - registro gastos'!$D$3:$D$300,'Enero - registro gastos'!$E$3:$E$300,Ene!$H$27,'Enero - registro gastos'!$F$3:$F$300,Ene!H28) -> 0 | L28: =J28-K28 -> 0
B29: Deuda tarjeta Un | D29: 3917065 | E29: =SUMIFS('Enero - registro gastos'!$D$3:$D$300,'Enero - registro gastos'!$E$3:$E$300,Ene!$B$27,'Enero - registro gastos'!$F$3:$F$300,Ene!B29) -> 3917064.8 | F29: =D29-E29 -> 0.2 | H29: Regalos cumpleaños | J29: 150000 | K29: =SUMIFS('Enero - registro gastos'!$D$3:$D$300,'Enero - registro gastos'!$E$3:$E$300,Ene!$H$27,'Enero - registro gastos'!$F$3:$F$300,Ene!H29) -> 0 | L29: =J29-K29 -> 150000
B30: Deuda Banco de occidente | E30: =SUMIFS('Enero - registro gastos'!$D$3:$D$300,'Enero - registro gastos'!$E$3:$E$300,Ene!$B$27,'Enero - registro gastos'!$F$3:$F$300,Ene!B30) -> 0 | F30: =D30-E30 -> 0 | H30: Caridad | J30: 55000 | K30: =SUMIFS('Enero - registro gastos'!$D$3:$D$300,'Enero - registro gastos'!$E$3:$E$300,Ene!$H$27,'Enero - registro gastos'!$F$3:$F$300,Ene!H30) -> 55000 | L30: =J30-K30 -> 0
B31: Deuda Estudio | E31: =SUMIFS('Enero - registro gastos'!$D$3:$D$300,'Enero - registro gastos'!$E$3:$E$300,Ene!$B$27,'Enero - registro gastos'!$F$3:$F$300,Ene!B31) -> 0 | F31: =D31-E31 -> 0 | K31: =SUMIFS('Enero - registro gastos'!$D$3:$D$300,'Enero - registro gastos'!$E$3:$E$300,Ene!$H$27,'Enero - registro gastos'!$F$3:$F$300,Ene!H31) -> 0 | L31: =J31-K31 -> 0
B32: Carro | E32: =SUMIFS('Enero - registro gastos'!$D$3:$D$300,'Enero - registro gastos'!$E$3:$E$300,Ene!$B$27,'Enero - registro gastos'!$F$3:$F$300,Ene!B32) -> 0 | F32: =D32-E32 -> 0 | K32: =SUMIFS('Enero - registro gastos'!$D$3:$D$300,'Enero - registro gastos'!$E$3:$E$300,Ene!$H$27,'Enero - registro gastos'!$F$3:$F$300,Ene!H32) -> 0 | L32: =J32-K32 -> 0
E33: =SUMIFS('Enero - registro gastos'!$D$3:$D$300,'Enero - registro gastos'!$E$3:$E$300,Ene!$B$27,'Enero - registro gastos'!$F$3:$F$300,Ene!B33) -> 0 | F33: =D33-E33 -> 0 | K33: =SUMIFS('Enero - registro gastos'!$D$3:$D$300,'Enero - registro gastos'!$E$3:$E$300,Ene!$H$27,'Enero - registro gastos'!$F$3:$F$300,Ene!H33) -> 0 | L33: =J33-K33 -> 0
E34: =SUMIFS('Enero - registro gastos'!$D$3:$D$300,'Enero - registro gastos'!$E$3:$E$300,Ene!$B$27,'Enero - registro gastos'!$F$3:$F$300,Ene!B34) -> 0 | F34: =D34-E34 -> 0 | K34: =SUMIFS('Enero - registro gastos'!$D$3:$D$300,'Enero - registro gastos'!$E$3:$E$300,Ene!$H$27,'Enero - registro gastos'!$F$3:$F$300,Ene!H34) -> 0 | L34: =J34-K34 -> 0
E35: =SUMIFS('Enero - registro gastos'!$D$3:$D$300,'Enero - registro gastos'!$E$3:$E$300,Ene!$B$27,'Enero - registro gastos'!$F$3:$F$300,Ene!B35) -> 0 | F35: =D35-E35 -> 0 | K35: =SUMIFS('Enero - registro gastos'!$D$3:$D$300,'Enero - registro gastos'!$E$3:$E$300,Ene!$H$27,'Enero - registro gastos'!$F$3:$F$300,Ene!H35) -> 0 | L35: =J35-K35 -> 0
B36: Subtotal | D36: =SUM(D28:D35) -> 3917065 | E36: =SUM(E28:E35) -> 3917064.8 | F36: =D36-E36 -> 0.2 | H36: Subtotal | J36: =SUM(J28:J35) -> 205000 | K36: =SUM(K28:K35) -> 55000 | L36: =J36-K36 -> 150000
B38: CASA | C38: Ahorro | D38: Presupuesto | E38: Gasto | F38: Disponible | H38: TRANSPORTE | I38: Ahorro | J38: Presupuesto | K38: Gasto | L38: Disponible
B39: Limpieza | E39: =SUMIFS('Enero - registro gastos'!$D$3:$D$300,'Enero - registro gastos'!$E$3:$E$300,Ene!$B$38,'Enero - registro gastos'!$F$3:$F$300,Ene!B39) -> 0 | F39: =D39-E39 -> 0 | H39: Uber/taxi | K39: =SUMIFS('Enero - registro gastos'!$D$3:$D$300,'Enero - registro gastos'!$E$3:$E$300,Ene!$H$38,'Enero - registro gastos'!$F$3:$F$300,Ene!H39) -> 0 | L39: =J39-K39 -> 0
B40: Mantenimiento | E40: =SUMIFS('Enero - registro gastos'!$D$3:$D$300,'Enero - registro gastos'!$E$3:$E$300,Ene!$B$38,'Enero - registro gastos'!$F$3:$F$300,Ene!B40) -> 0 | F40: =D40-E40 -> 0 | H40: Estacionamiento | K40: =SUMIFS('Enero - registro gastos'!$D$3:$D$300,'Enero - registro gastos'!$E$3:$E$300,Ene!$H$38,'Enero - registro gastos'!$F$3:$F$300,Ene!H40) -> 0 | L40: =J40-K40 -> 0
B41: Muebles | E41: =SUMIFS('Enero - registro gastos'!$D$3:$D$300,'Enero - registro gastos'!$E$3:$E$300,Ene!$B$38,'Enero - registro gastos'!$F$3:$F$300,Ene!B41) -> 0 | F41: =D41-E41 -> 0 | H41: Mantenimiento | K41: =SUMIFS('Enero - registro gastos'!$D$3:$D$300,'Enero - registro gastos'!$E$3:$E$300,Ene!$H$38,'Enero - registro gastos'!$F$3:$F$300,Ene!H41) -> 0 | L41: =J41-K41 -> 0
B42: Impuestos | E42: =SUMIFS('Enero - registro gastos'!$D$3:$D$300,'Enero - registro gastos'!$E$3:$E$300,Ene!$B$38,'Enero - registro gastos'!$F$3:$F$300,Ene!B42) -> 0 | F42: =D42-E42 -> 0 | H42: Impuestos lulo | I42: SI | J42: 500000 | K42: =SUMIFS('Enero - registro gastos'!$D$3:$D$300,'Enero - registro gastos'!$E$3:$E$300,Ene!$H$38,'Enero - registro gastos'!$F$3:$F$300,Ene!H42) -> 0 | L42: =J42-K42 -> 500000
E43: =SUMIFS('Enero - registro gastos'!$D$3:$D$300,'Enero - registro gastos'!$E$3:$E$300,Ene!$B$38,'Enero - registro gastos'!$F$3:$F$300,Ene!B43) -> 0 | F43: =D43-E43 -> 0 | H43: Panapass/Peaje | J43: 20000 | K43: =SUMIFS('Enero - registro gastos'!$D$3:$D$300,'Enero - registro gastos'!$E$3:$E$300,Ene!$H$38,'Enero - registro gastos'!$F$3:$F$300,Ene!H43) -> 0 | L43: =J43-K43 -> 20000
E44: =SUMIFS('Enero - registro gastos'!$D$3:$D$300,'Enero - registro gastos'!$E$3:$E$300,Ene!$B$38,'Enero - registro gastos'!$F$3:$F$300,Ene!B44) -> 0 | F44: =D44-E44 -> 0 | K44: =SUMIFS('Enero - registro gastos'!$D$3:$D$300,'Enero - registro gastos'!$E$3:$E$300,Ene!$H$38,'Enero - registro gastos'!$F$3:$F$300,Ene!H44) -> 0 | L44: =J44-K44 -> 0
E45: =SUMIFS('Enero - registro gastos'!$D$3:$D$300,'Enero - registro gastos'!$E$3:$E$300,Ene!$B$38,'Enero - registro gastos'!$F$3:$F$300,Ene!B45) -> 0 | F45: =D45-E45 -> 0 | K45: =SUMIFS('Enero - registro gastos'!$D$3:$D$300,'Enero - registro gastos'!$E$3:$E$300,Ene!$H$38,'Enero - registro gastos'!$F$3:$F$300,Ene!H45) -> 0 | L45: =J45-K45 -> 0
...

Sheet Enero - registro gastos
B2: Fecha | C2: Compra | D2: Valor | E2: Categoría | F2: Sub Categoría | J2: Categoría
B3: 45658 | C3: Transferencia a Andrés BBC y Ramen | D3: 63000 | E3: ALIMENTACIÓN | F3: Restaurantes | H3: =E3&F3 -> ALIMENTACIÓNRestaurantes | I3: =IFERROR(VLOOKUP(H3,$AP:$AQ,2,FALSE),"Error") -> ALIMENTACIÓNRestaurantes | J3: =IF(I3="Error","Revisa tu subcategoria",IF(I3=H3,"Es correcto",IF(H3="blanco","",""))) -> Es correcto | AN3: CATEGORÍA | AO3: SUBCATEGORIA
B4: 45659 | C4: Tabla de Quesos | D4: 54270 | E4: ALIMENTACIÓN | F4: Restaurantes | H4: =E4&F4 -> ALIMENTACIÓNRestaurantes | I4: =IFERROR(VLOOKUP(H4,$AP:$AQ,2,FALSE),"Error") -> ALIMENTACIÓNRestaurantes | J4: =IF(I4="Error","Revisa tu subcategoria",IF(I4=H4,"Es correcto",IF(H4="blanco","",""))) -> Es correcto | AN4: =Ene!$B$12 -> NECESIDADES BÁSICAS | AO4: =Ene!B13 -> Arriendo/Hipoteca | AP4: =AN4&AO4 -> NECESIDADES BÁSICASArriendo/Hipoteca | AQ4: =AP4 -> NECESIDADES BÁSICASArriendo/Hipoteca
B5: 45660 | C5: papitas y cositas | D5: =28620+5000 -> 33620 | E5: ALIMENTACIÓN | F5: Restaurantes | H5: =E5&F5 -> ALIMENTACIÓNRestaurantes | I5: =IFERROR(VLOOKUP(H5,$AP:$AQ,2,FALSE),"Error") -> ALIMENTACIÓNRestaurantes | J5: =IF(I5="Error","Revisa tu subcategoria",IF(I5=H5,"Es correcto",IF(H5="blanco","",""))) -> Es correcto | AN5: =Ene!$B$12 -> NECESIDADES BÁSICAS | AO5: =Ene!B14 -> Telefono/ Celular | AP5: =AN5&AO5 -> NECESIDADES BÁSICASTelefono/ Celular | AQ5: =AP5 -> NECESIDADES BÁSICASTelefono/ Celular
B6: 45660 | C6: Cobro automatico | D6: 55000 | E6: REGALOS/ CARIDAD | F6: Caridad | H6: =E6&F6 -> REGALOS/ CARIDADCaridad | I6: =IFERROR(VLOOKUP(H6,$AP:$AQ,2,FALSE),"Error") -> REGALOS/ CARIDADCaridad | J6: =IF(I6="Error","Revisa tu subcategoria",IF(I6=H6,"Es correcto",IF(H6="blanco","",""))) -> Es correcto | AN6: =Ene!$B$12 -> NECESIDADES BÁSICAS | AO6: =Ene!B15 -> Electricidad | AP6: =AN6&AO6 -> NECESIDADES BÁSICASElectricidad | AQ6: =AP6 -> NECESIDADES BÁSICASElectricidad
B7: 45660 | C7: Cobro automatico | D7: 14950 | E7: ENTRETENIMIENTO | F7: hbo | H7: =E7&F7 -> ENTRETENIMIENTOhbo | I7: =IFERROR(VLOOKUP(H7,$AP:$AQ,2,FALSE),"Error") -> ENTRETENIMIENTOhbo | J7: =IF(I7="Error","Revisa tu subcategoria",IF(I7=H7,"Es correcto",IF(H7="blanco","",""))) -> Es correcto | AN7: =Ene!$B$12 -> NECESIDADES BÁSICAS | AO7: =Ene!B16 -> Agua | AP7: =AN7&AO7 -> NECESIDADES BÁSICASAgua | AQ7: =AP7 -> NECESIDADES BÁSICASAgua
B8: 45660 | C8: Cobro automatico | D8: 44900 | E8: ENTRETENIMIENTO | F8: Netflix | H8: =E8&F8 -> ENTRETENIMIENTONetflix | I8: =IFERROR(VLOOKUP(H8,$AP:$AQ,2,FALSE),"Error") -> ENTRETENIMIENTONetflix | J8: =IF(H8=I8,"Es correcto","Revisa tu subcategoria") -> Es correcto | AN8: =Ene!$B$12 -> NECESIDADES BÁSICAS | AO8: =Ene!B17 -> Gas | AP8: =AN8&AO8 -> NECESIDADES BÁSICASGas | AQ8: =AP8 -> NECESIDADES BÁSICASGas
B9: 45660 | C9: Pago mes | D9: 142988 | E9: NECESIDADES BÁSICAS | F9: Cable/Internet | H9: =E9&F9 -> NECESIDADES BÁSICASCable/Internet | I9: =IFERROR(VLOOKUP(H9,$AP:$AQ,2,FALSE),"Error") -> NECESIDADES BÁSICASCable/Internet | J9: =IF(H9=I9,"Es correcto","Revisa tu subcategoria") -> Es correcto | AN9: =Ene!$B$12 -> NECESIDADES BÁSICAS | AO9: =Ene!B18 -> Cable/Internet | AP9: =AN9&AO9 -> NECESIDADES BÁSICASCable/Internet | AQ9: =AP9 -> NECESIDADES BÁSICASCable/Internet
B10: 45660 | C10: Pago mes | D10: 148241.73 | E10: ENTRETENIMIENTO | F10: Deporte | H10: =E10&F10 -> ENTRETENIMIENTODeporte | I10: =IFERROR(VLOOKUP(H10,$AP:$AQ,2,FALSE),"Error") -> ENTRETENIMIENTODeporte | J10: =IF(H10=I10,"Es correcto","Revisa tu subcategoria") -> Es correcto | AN10: =Ene!$B$12 -> NECESIDADES BÁSICAS | AO10: =Ene!B19 -> Super Mercado | AP10: =AN10&AO10 -> NECESIDADES BÁSICASSuper Mercado | AQ10: =AP10 -> NECESIDADES BÁSICASSuper Mercado
B11: 45660 | C11: Pago mes | D11: 77988 | E11: NECESIDADES BÁSICAS | F11: Telefono/ Celular | H11: =E11&F11 -> NECESIDADES BÁSICASTelefono/ Celular | I11: =IFERROR(VLOOKUP(H11,$AP:$AQ,2,FALSE),"Error") -> NECESIDADES BÁSICASTelefono/ Celular | J11: =IF(H11=I11,"Es correcto","Revisa tu subcategoria") -> Es correcto | AN11: =Ene!$B$12 -> NECESIDADES BÁSICAS | AO11: =Ene!B20 -> Gasolina | AP11: =AN11&AO11 -> NECESIDADES BÁSICASGasolina | AQ11: =AP11 -> NECESIDADES BÁSICASGasolina
B12: 45660 | C12: Pago mes | D12: 28650 | E12: ALIMENTACIÓN | F12: Rappi | H12: =E12&F12 -> ALIMENTACIÓNRappi | I12: =IFERROR(VLOOKUP(H12,$AP:$AQ,2,FALSE),"Error") -> ALIMENTACIÓNRappi | J12: =IF(H12=I12,"Es correcto","Revisa tu subcategoria") -> Es correcto | AN12: =Ene!$B$12 -> NECESIDADES BÁSICAS | AO12: =Ene!B21 -> Bus | AP12: =AN12&AO12 -> NECESIDADES BÁSICASBus | AQ12: =AP12 -> NECESIDADES BÁSICASBus
B13: 45661 | C13: Deudas Nu | D13: 3917064.8 | E13: DEUDAS | F13: Deuda tarjeta Un | H13: =E13&F13 -> DEUDASDeuda tarjeta Un | I13: =IFERROR(VLOOKUP(H13,$AP:$AQ,2,FALSE),"Error") -> DEUDASDeuda tarjeta Un | J13: =IF(H13=I13,"Es correcto","Revisa tu subcategoria") -> Es correcto | AN13: =Ene!$B$12 -> NECESIDADES BÁSICAS | AO13: =Ene!B22 -> 0 | AP13: =AN13&AO13 -> NECESIDADES BÁSICAS0 | AQ13: =AP13 -> NECESIDADES BÁSICAS0
B14: 45661 | C14: Apple | D14: 12900 | E14: ENTRETENIMIENTO | F14: Apple cloud | H14: =E14&F14 -> ENTRETENIMIENTOApple cloud | I14: =IFERROR(VLOOKUP(H14,$AP:$AQ,2,FALSE),"Error") -> ENTRETENIMIENTOApple cloud | J14: =IF(H14=I14,"Es correcto","Revisa tu subcategoria") -> Es correcto | AN14: =Ene!$B$12 -> NECESIDADES BÁSICAS | AO14: =Ene!B23 -> 0 | AP14: =AN14&AO14 -> NECESIDADES BÁSICAS0 | AQ14: =AP14 -> NECESIDADES BÁSICAS0
B15: 45659 | C15: Cine Avatar | D15: 144000 | E15: ENTRETENIMIENTO | F15: Cine | H15: =E15&F15 -> ENTRETENIMIENTOCine | I15: =IFERROR(VLOOKUP(H15,$AP:$AQ,2,FALSE),"Error") -> ENTRETENIMIENTOCine | J15: =IF(H15=I15,"Es correcto","Revisa tu subcategoria") -> Es correcto | AN15: =Ene!$B$12 -> NECESIDADES BÁSICAS | AO15: =Ene!B24 -> 0 | AP15: =AN15&AO15 -> NECESIDADES BÁSICAS0 | AQ15: =AP15 -> NECESIDADES BÁSICAS0
B16: 45663 | C16: Cine Zootopia | D16: 100000 | E16: ENTRETENIMIENTO | F16: Cine | H16: =E16&F16 -> ENTRETENIMIENTOCine | I16: =IFERROR(VLOOKUP(H16,$AP:$AQ,2,FALSE),"Error") -> ENTRETENIMIENTOCine | J16: =IF(H16=I16,"Es correcto","Revisa tu subcategoria") -> Es correcto | AN16: =Ene!$H$12 -> AHORROS | AO16: =Ene!H13 -> Efectivo | AP16: =AN16&AO16 -> AHORROSEfectivo | AQ16: =AP16 -> AHORROSEfectivo
H17: =E17&F17 | I17: =IFERROR(VLOOKUP(H17,$AP:$AQ,2,FALSE),"Error") -> Error | J17: =IF(H17=I17,"Es correcto","Revisa tu subcategoria") -> Revisa tu subcategoria | AN17: =Ene!$H$12 -> AHORROS | AO17: =Ene!H14 -> Cuenta Bancol | AP17: =AN17&AO17 -> AHORROSCuenta Bancol | AQ17: =AP17 -> AHORROSCuenta Bancol
H18: =E18&F18 | I18: =IFERROR(VLOOKUP(H18,$AP:$AQ,2,FALSE),"Error") -> Error | J18: =IF(H18=I18,"Es correcto","Revisa tu subcategoria") -> Revisa tu subcategoria | AN18: =Ene!$H$12 -> AHORROS | AO18: =Ene!H15 -> pension voluntaria ahorro casa | AP18: =AN18&AO18 -> AHORROSpension voluntaria ahorro casa | AQ18: =AP18 -> AHORROSpension voluntaria ahorro casa
H19: =E19&F19 | I19: =IFERROR(VLOOKUP(H19,$AP:$AQ,2,FALSE),"Error") -> Error | J19: =IF(H19=I19,"Es correcto","Revisa tu subcategoria") -> Revisa tu subcategoria | AN19: =Ene!$H$12 -> AHORROS | AO19: =Ene!H16 -> Investor trust 1200 | AP19: =AN19&AO19 -> AHORROSInvestor trust 1200 | AQ19: =AP19 -> AHORROSInvestor trust 1200
H20: =E20&F20 | I20: =IFERROR(VLOOKUP(H20,$AP:$AQ,2,FALSE),"Error") -> Error | J20: =IF(H20=I20,"Es correcto","Revisa tu subcategoria") -> Revisa tu subcategoria | AN20: =Ene!$H$12 -> AHORROS | AO20: =Ene!H17 -> Investor trust 2400 | AP20: =AN20&AO20 -> AHORROSInvestor trust 2400 | AQ20: =AP20 -> AHORROSInvestor trust 2400
H21: =E21&F21 | I21: =IFERROR(VLOOKUP(H21,$AP:$AQ,2,FALSE),"Error") -> Error | J21: =IF(H21=I21,"Es correcto","Revisa tu subcategoria") -> Revisa tu subcategoria | AN21: =Ene!$H$12 -> AHORROS | AO21: =Ene!H18 -> poliza pensiones skandia | AP21: =AN21&AO21 -> AHORROSpoliza pensiones skandia | AQ21: =AP21 -> AHORROSpoliza pensiones skandia
H22: =E22&F22 | I22: =IFERROR(VLOOKUP(H22,$AP:$AQ,2,FALSE),"Error") -> Error | J22: =IF(H22=I22,"Es correcto","Revisa tu subcategoria") -> Revisa tu subcategoria | AN22: =Ene!$H$12 -> AHORROS | AO22: =Ene!H19 -> Fondo de emergencia lulo | AP22: =AN22&AO22 -> AHORROSFondo de emergencia lulo | AQ22: =AP22 -> AHORROSFondo de emergencia lulo
H23: =E23&F23 | I23: =IFERROR(VLOOKUP(H23,$AP:$AQ,2,FALSE),"Error") -> Error | J23: =IF(H23=I23,"Es correcto","Revisa tu subcategoria") -> Revisa tu subcategoria | AN23: =Ene!$H$12 -> AHORROS | AO23: =Ene!H20 -> Littio | AP23: =AN23&AO23 -> AHORROSLittio | AQ23: =AP23 -> AHORROSLittio
H24: =E24&F24 | I24: =IFERROR(VLOOKUP(H24,$AP:$AQ,2,FALSE),"Error") -> Error | J24: =IF(H24=I24,"Es correcto","Revisa tu subcategoria") -> Revisa tu subcategoria | AN24: =Ene!$H$12 -> AHORROS | AO24: =Ene!H21 -> Nequi | AP24: =AN24&AO24 -> AHORROSNequi | AQ24: =AP24 -> AHORROSNequi
H25: =E25&F25 | I25: =IFERROR(VLOOKUP(H25,$AP:$AQ,2,FALSE),"Error") -> Error | J25: =IF(H25=I25,"Es correcto","Revisa tu subcategoria") -> Revisa tu subcategoria | AN25: =Ene!$H$12 -> AHORROS | AO25: =Ene!H22 -> viajes varios | AP25: =AN25&AO25 -> AHORROSviajes varios | AQ25: =AP25 -> AHORROSviajes varios
H26: =E26&F26 | I26: =IFERROR(VLOOKUP(H26,$AP:$AQ,2,FALSE),"Error") -> Error | J26: =IF(H26=I26,"Es correcto","Revisa tu subcategoria") -> Revisa tu subcategoria | AN26: =Ene!$H$12 -> AHORROS | AO26: =Ene!H23 -> Viaje Japon lulo | AP26: =AN26&AO26 -> AHORROSViaje Japon lulo | AQ26: =AP26 -> AHORROSViaje Japon lulo
H27: =E27&F27 | I27: =IFERROR(VLOOKUP(H27,$AP:$AQ,2,FALSE),"Error") -> Error | J27: =IF(H27=I27,"Es correcto","Revisa tu subcategoria") -> Revisa tu subcategoria | AN27: =Ene!$H$12 -> AHORROS | AO27: =Ene!H24 -> Viaje Estados unidos lulo | AP27: =AN27&AO27 -> AHORROSViaje Estados unidos lulo | AQ27: =AP27 -> AHORROSViaje Estados unidos lulo
H28: =E28&F28 | I28: =IFERROR(VLOOKUP(H28,$AP:$AQ,2,FALSE),"Error") -> Error | J28: =IF(H28=I28,"Es correcto","Revisa tu subcategoria") -> Revisa tu subcategoria | AN28: =Ene!$B$27 -> DEUDAS | AO28: =Ene!B28 -> Deuda Carro | AP28: =AN28&AO28 -> DEUDASDeuda Carro | AQ28: =AP28 -> DEUDASDeuda Carro
H29: =E29&F29 | I29: =IFERROR(VLOOKUP(H29,$AP:$AQ,2,FALSE),"Error") -> Error | J29: =IF(H29=I29,"Es correcto","Revisa tu subcategoria") -> Revisa tu subcategoria | AN29: =Ene!$B$27 -> DEUDAS | AO29: =Ene!B29 -> Deuda tarjeta Un | AP29: =AN29&AO29 -> DEUDASDeuda tarjeta Un | AQ29: =AP29 -> DEUDASDeuda tarjeta Un
H30: =E30&F30 | I30: =IFERROR(VLOOKUP(H30,$AP:$AQ,2,FALSE),"Error") -> Error | J30: =IF(H30=I30,"Es correcto","Revisa tu subcategoria") -> Revisa tu subcategoria | AN30: =Ene!$B$27 -> DEUDAS | AO30: =Ene!B30 -> Deuda Banco de occidente | AP30: =AN30&AO30 -> DEUDASDeuda Banco de occidente | AQ30: =AP30 -> DEUDASDeuda Banco de occidente
H31: =E31&F31 | I31: =IFERROR(VLOOKUP(H31,$AP:$AQ,2,FALSE),"Error") -> Error | J31: =IF(H31=I31,"Es correcto","Revisa tu subcategoria") -> Revisa tu subcategoria | AN31: =Ene!$B$27 -> DEUDAS | AO31: =Ene!B31 -> Deuda Estudio | AP31: =AN31&AO31 -> DEUDASDeuda Estudio | AQ31: =AP31 -> DEUDASDeuda Estudio
H32: =E32&F32 | I32: =IFERROR(VLOOKUP(H32,$AP:$AQ,2,FALSE),"Error") -> Error | J32: =IF(H32=I32,"Es correcto","Revisa tu subcategoria") -> Revisa tu subcategoria | AN32: =Ene!$B$27 -> DEUDAS | AO32: =Ene!B32 -> Carro | AP32: =AN32&AO32 -> DEUDASCarro | AQ32: =AP32 -> DEUDASCarro
H33: =E33&F33 | I33: =IFERROR(VLOOKUP(H33,$AP:$AQ,2,FALSE),"Error") -> Error | J33: =IF(H33=I33,"Es correcto","Revisa tu subcategoria") -> Revisa tu subcategoria | AN33: =Ene!$B$27 -> DEUDAS | AO33: =Ene!B33 -> 0 | AP33: =AN33&AO33 -> DEUDAS0 | AQ33: =AP33 -> DEUDAS0
H34: =E34&F34 | I34: =IFERROR(VLOOKUP(H34,$AP:$AQ,2,FALSE),"Error") -> Error | J34: =IF(H34=I34,"Es correcto","Revisa tu subcategoria") -> Revisa tu subcategoria | AN34: =Ene!$B$27 -> DEUDAS | AO34: =Ene!B34 -> 0 | AP34: =AN34&AO34 -> DEUDAS0 | AQ34: =AP34 -> DEUDAS0
H35: =E35&F35 | I35: =IFERROR(VLOOKUP(H35,$AP:$AQ,2,FALSE),"Error") -> Error | J35: =IF(H35=I35,"Es correcto","Revisa tu subcategoria") -> Revisa tu subcategoria | AN35: =Ene!$B$27 -> DEUDAS | AO35: =Ene!B35 -> 0 | AP35: =AN35&AO35 -> DEUDAS0 | AQ35: =AP35 -> DEUDAS0
H36: =E36&F36 | I36: =IFERROR(VLOOKUP(H36,$AP:$AQ,2,FALSE),"Error") -> Error | J36: =IF(H36=I36,"Es correcto","Revisa tu subcategoria") -> Revisa tu subcategoria | AN36: =Ene!$H$27 -> REGALOS/ CARIDAD | AO36: =Ene!H28 -> Regalos Navidad | AP36: =AN36&AO36 -> REGALOS/ CARIDADRegalos Navidad | AQ36: =AP36 -> REGALOS/ CARIDADRegalos Navidad
H37: =E37&F37 | I37: =IFERROR(VLOOKUP(H37,$AP:$AQ,2,FALSE),"Error") -> Error | J37: =IF(H37=I37,"Es correcto","Revisa tu subcategoria") -> Revisa tu subcategoria | AN37: =Ene!$H$27 -> REGALOS/ CARIDAD | AO37: =Ene!H29 -> Regalos cumpleaños | AP37: =AN37&AO37 -> REGALOS/ CARIDADRegalos cumpleaños | AQ37: =AP37 -> REGALOS/ CARIDADRegalos cumpleaños
H38: =E38&F38 | I38: =IFERROR(VLOOKUP(H38,$AP:$AQ,2,FALSE),"Error") -> Error | J38: =IF(H38=I38,"Es correcto","Revisa tu subcategoria") -> Revisa tu subcategoria | AN38: =Ene!$H$27 -> REGALOS/ CARIDAD | AO38: =Ene!H30 -> Caridad | AP38: =AN38&AO38 -> REGALOS/ CARIDADCaridad | AQ38: =AP38 -> REGALOS/ CARIDADCaridad
H39: =E39&F39 | I39: =IFERROR(VLOOKUP(H39,$AP:$AQ,2,FALSE),"Error") -> Error | J39: =IF(H39=I39,"Es correcto","Revisa tu subcategoria") -> Revisa tu subcategoria | AN39: =Ene!$H$27 -> REGALOS/ CARIDAD | AO39: =Ene!H31 -> 0 | AP39: =AN39&AO39 -> REGALOS/ CARIDAD0 | AQ39: =AP39 -> REGALOS/ CARIDAD0
H40: =E40&F40 | I40: =IFERROR(VLOOKUP(H40,$AP:$AQ,2,FALSE),"Error") -> Error | J40: =IF(H40=I40,"Es correcto","Revisa tu subcategoria") -> Revisa tu subcategoria | AN40: =Ene!$H$27 -> REGALOS/ CARIDAD | AO40: =Ene!H32 -> 0 | AP40: =AN40&AO40 -> REGALOS/ CARIDAD0 | AQ40: =AP40 -> REGALOS/ CARIDAD0
H41: =E41&F41 | I41: =IFERROR(VLOOKUP(H41,$AP:$AQ,2,FALSE),"Error") -> Error | J41: =IF(H41=I41,"Es correcto","Revisa tu subcategoria") -> Revisa tu subcategoria | AN41: =Ene!$H$27 -> REGALOS/ CARIDAD | AO41: =Ene!H33 -> 0 | AP41: =AN41&AO41 -> REGALOS/ CARIDAD0 | AQ41: =AP41 -> REGALOS/ CARIDAD0
...

Sheet Feb
U1: =B13 -> Arriendo/Hipoteca
B2: PRESUPUESTO MENSUAL
B4: Ingreso Estimado | C4: Salario
C10: Total Ingreso Mensual | E10: =SUM(E4:E9) -> 0 | H10: Balance (Ingreso vs Presupuesto) | K10: =E10-SUM(D25,D36,D55,D65,D79,D88,D98,J25,J36,J55,J65,J88,J98,D108,J108,D46,J46,J79) -> 0 | M10: =IF(K10=0,"El presupuesto está listo","OJO! TiFeb que sumar cero") -> El presupuesto está listo
B12: NECESIDADES BÁSICAS | C12: Ahorro | D12: Presupuesto | E12: Gasto | F12: Disponible | H12: AHORROS | I12: Ahorro | J12: Presupuesto | K12: Gasto | L12: Disponible
B13: Arriendo/Hipoteca | E13: =SUMIFS('Feb - registro gastos'!$D$3:$D$300,'Feb - registro gastos'!$E$3:$E$300,Feb!$B$12,'Feb - registro gastos'!$F$3:$F$300,Feb!B13) -> 0 | F13: =D13-E13 -> 0 | H13: Fondo de Emergencia | K13: =SUMIFS('Feb - registro gastos'!$D$3:$D$300,'Feb - registro gastos'!$E$3:$E$300,Feb!$H$12,'Feb - registro gastos'!$F$3:$F$300,Feb!H13) -> 0 | L13: =J13-K13 -> 0
B14: Telefono/ Celular | E14: =SUMIFS('Feb - registro gastos'!$D$3:$D$300,'Feb - registro gastos'!$E$3:$E$300,Feb!$B$12,'Feb - registro gastos'!$F$3:$F$300,Feb!B14) -> 0 | F14: =D14-E14 -> 0 | H14: Fondo de Pensión | K14: =SUMIFS('Feb - registro gastos'!$D$3:$D$300,'Feb - registro gastos'!$E$3:$E$300,Feb!$H$12,'Feb - registro gastos'!$F$3:$F$300,Feb!H14) -> 0 | L14: =J14-K14 -> 0
B15: Electricidad | E15: =SUMIFS('Feb - registro gastos'!$D$3:$D$300,'Feb - registro gastos'!$E$3:$E$300,Feb!$B$12,'Feb - registro gastos'!$F$3:$F$300,Feb!B15) -> 0 | F15: =D15-E15 -> 0 | H15: Fondo de Educación | K15: =SUMIFS('Feb - registro gastos'!$D$3:$D$300,'Feb - registro gastos'!$E$3:$E$300,Feb!$H$12,'Feb - registro gastos'!$F$3:$F$300,Feb!H15) -> 0 | L15: =J15-K15 -> 0
B16: Agua | E16: =SUMIFS('Feb - registro gastos'!$D$3:$D$300,'Feb - registro gastos'!$E$3:$E$300,Feb!$B$12,'Feb - registro gastos'!$F$3:$F$300,Feb!B16) -> 0 | F16: =D16-E16 -> 0 | H16: Cuota Inicial Casa | K16: =SUMIFS('Feb - registro gastos'!$D$3:$D$300,'Feb - registro gastos'!$E$3:$E$300,Feb!$H$12,'Feb - registro gastos'!$F$3:$F$300,Feb!H16) -> 0 | L16: =J16-K16 -> 0
B17: Gas | E17: =SUMIFS('Feb - registro gastos'!$D$3:$D$300,'Feb - registro gastos'!$E$3:$E$300,Feb!$B$12,'Feb - registro gastos'!$F$3:$F$300,Feb!B17) -> 0 | F17: =D17-E17 -> 0 | H17: Aporte a Capital | K17: =SUMIFS('Feb - registro gastos'!$D$3:$D$300,'Feb - registro gastos'!$E$3:$E$300,Feb!$H$12,'Feb - registro gastos'!$F$3:$F$300,Feb!H17) -> 0 | L17: =J17-K17 -> 0
B18: Cable/Internet | E18: =SUMIFS('Feb - registro gastos'!$D$3:$D$300,'Feb - registro gastos'!$E$3:$E$300,Feb!$B$12,'Feb - registro gastos'!$F$3:$F$300,Feb!B18) -> 0 | F18: =D18-E18 -> 0 | K18: =SUMIFS('Feb - registro gastos'!$D$3:$D$300,'Feb - registro gastos'!$E$3:$E$300,Feb!$H$12,'Feb - registro gastos'!$F$3:$F$300,Feb!H18) -> 0 | L18: =J18-K18 -> 0
B19: Super Mercado | E19: =SUMIFS('Feb - registro gastos'!$D$3:$D$300,'Feb - registro gastos'!$E$3:$E$300,Feb!$B$12,'Feb - registro gastos'!$F$3:$F$300,Feb!B19) -> 0 | F19: =D19-E19 -> 0 | K19: =SUMIFS('Feb - registro gastos'!$D$3:$D$300,'Feb - registro gastos'!$E$3:$E$300,Feb!$H$12,'Feb - registro gastos'!$F$3:$F$300,Feb!H19) -> 0 | L19: =J19-K19 -> 0
B20: Gasolina | E20: =SUMIFS('Feb - registro gastos'!$D$3:$D$300,'Feb - registro gastos'!$E$3:$E$300,Feb!$B$12,'Feb - registro gastos'!$F$3:$F$300,Feb!B20) -> 0 | F20: =D20-E20 -> 0 | K20: =SUMIFS('Feb - registro gastos'!$D$3:$D$300,'Feb - registro gastos'!$E$3:$E$300,Feb!$H$12,'Feb - registro gastos'!$F$3:$F$300,Feb!H20) -> 0 | L20: =J20-K20 -> 0
B21: Bus | E21: =SUMIFS('Feb - registro gastos'!$D$3:$D$300,'Feb - registro gastos'!$E$3:$E$300,Feb!$B$12,'Feb - registro gastos'!$F$3:$F$300,Feb!B21) -> 0 | F21: =D21-E21 -> 0 | K21: =SUMIFS('Feb - registro gastos'!$D$3:$D$300,'Feb - registro gastos'!$E$3:$E$300,Feb!$H$12,'Feb - registro gastos'!$F$3:$F$300,Feb!H21) -> 0 | L21: =J21-K21 -> 0
E22: =SUMIFS('Feb - registro gastos'!$D$3:$D$300,'Feb - registro gastos'!$E$3:$E$300,Feb!$B$12,'Feb - registro gastos'!$F$3:$F$300,Feb!B22) -> 0 | F22: =D22-E22 -> 0 | K22: =SUMIFS('Feb - registro gastos'!$D$3:$D$300,'Feb - registro gastos'!$E$3:$E$300,Feb!$H$12,'Feb - registro gastos'!$F$3:$F$300,Feb!H22) -> 0 | L22: =J22-K22 -> 0
E23: =SUMIFS('Feb - registro gastos'!$D$3:$D$300,'Feb - registro gastos'!$E$3:$E$300,Feb!$B$12,'Feb - registro gastos'!$F$3:$F$300,Feb!B23) -> 0 | F23: =D23-E23 -> 0 | K23: =SUMIFS('Feb - registro gastos'!$D$3:$D$300,'Feb - registro gastos'!$E$3:$E$300,Feb!$H$12,'Feb - registro gastos'!$F$3:$F$300,Feb!H23) -> 0 | L23: =J23-K23 -> 0
E24: =SUMIFS('Feb - registro gastos'!$D$3:$D$300,'Feb - registro gastos'!$E$3:$E$300,Feb!$B$12,'Feb - registro gastos'!$F$3:$F$300,Feb!B24) -> 0 | F24: =D24-E24 -> 0 | K24: =SUMIFS('Feb - registro gastos'!$D$3:$D$300,'Feb - registro gastos'!$E$3:$E$300,Feb!$H$12,'Feb - registro gastos'!$F$3:$F$300,Feb!H24) -> 0 | L24: =J24-K24 -> 0
B25: Subtotal | D25: =SUM(D13:D24) -> 0 | E25: =SUM(E13:E24) -> 0 | F25: =D25-E25 -> 0 | H25: Subtotal | J25: =SUM(J13:J24) -> 0 | K25: =SUM(K13:K24) -> 0 | L25: =J25-K25 -> 0
B27: DEUDAS | C27: Ahorro | D27: Presupuesto | E27: Gasto | F27: Disponible | H27: REGALOS/ CARIDAD | I27: Ahorro | J27: Presupuesto | K27: Gasto | L27: Disponible
B28: Deuda Carro | E28: =SUMIFS('Feb - registro gastos'!$D$3:$D$300,'Feb - registro gastos'!$E$3:$E$300,Feb!$B$27,'Feb - registro gastos'!$F$3:$F$300,Feb!B28) -> 0 | F28: =D28-E28 -> 0 | H28: Regalos Navidad | K28: =SUMIFS('Feb - registro gastos'!$D$3:$D$300,'Feb - registro gastos'!$E$3:$E$300,Feb!$H$27,'Feb - registro gastos'!$F$3:$F$300,Feb!H28) -> 0 | L28: =J28-K28 -> 0
B29: Deuda tarjeta 1 | E29: =SUMIFS('Feb - registro gastos'!$D$3:$D$300,'Feb - registro gastos'!$E$3:$E$300,Feb!$B$27,'Feb - registro gastos'!$F$3:$F$300,Feb!B29) -> 0 | F29: =D29-E29 -> 0 | H29: Regalos cumpleaños | K29: =SUMIFS('Feb - registro gastos'!$D$3:$D$300,'Feb - registro gastos'!$E$3:$E$300,Feb!$H$27,'Feb - registro gastos'!$F$3:$F$300,Feb!H29) -> 0 | L29: =J29-K29 -> 0
B30: Deuda tarjeta 2 | E30: =SUMIFS('Feb - registro gastos'!$D$3:$D$300,'Feb - registro gastos'!$E$3:$E$300,Feb!$B$27,'Feb - registro gastos'!$F$3:$F$300,Feb!B30) -> 0 | F30: =D30-E30 -> 0 | H30: Caridad | K30: =SUMIFS('Feb - registro gastos'!$D$3:$D$300,'Feb - registro gastos'!$E$3:$E$300,Feb!$H$27,'Feb - registro gastos'!$F$3:$F$300,Feb!H30) -> 0 | L30: =J30-K30 -> 0
B31: Deuda Estudio | E31: =SUMIFS('Feb - registro gastos'!$D$3:$D$300,'Feb - registro gastos'!$E$3:$E$300,Feb!$B$27,'Feb - registro gastos'!$F$3:$F$300,Feb!B31) -> 0 | F31: =D31-E31 -> 0 | K31: =SUMIFS('Feb - registro gastos'!$D$3:$D$300,'Feb - registro gastos'!$E$3:$E$300,Feb!$H$27,'Feb - registro gastos'!$F$3:$F$300,Feb!H31) -> 0 | L31: =J31-K31 -> 0
B32: Carro | E32: =SUMIFS('Feb - registro gastos'!$D$3:$D$300,'Feb - registro gastos'!$E$3:$E$300,Feb!$B$27,'Feb - registro gastos'!$F$3:$F$300,Feb!B32) -> 0 | F32: =D32-E32 -> 0 | K32: =SUMIFS('Feb - registro gastos'!$D$3:$D$300,'Feb - registro gastos'!$E$3:$E$300,Feb!$H$27,'Feb - registro gastos'!$F$3:$F$300,Feb!H32) -> 0 | L32: =J32-K32 -> 0
E33: =SUMIFS('Feb - registro gastos'!$D$3:$D$300,'Feb - registro gastos'!$E$3:$E$300,Feb!$B$27,'Feb - registro gastos'!$F$3:$F$300,Feb!B33) -> 0 | F33: =D33-E33 -> 0 | K33: =SUMIFS('Feb - registro gastos'!$D$3:$D$300,'Feb - registro gastos'!$E$3:$E$300,Feb!$H$27,'Feb - registro gastos'!$F$3:$F$300,Feb!H33) -> 0 | L33: =J33-K33 -> 0
E34: =SUMIFS('Feb - registro gastos'!$D$3:$D$300,'Feb - registro gastos'!$E$3:$E$300,Feb!$B$27,'Feb - registro gastos'!$F$3:$F$300,Feb!B34) -> 0 | F34: =D34-E34 -> 0 | K34: =SUMIFS('Feb - registro gastos'!$D$3:$D$300,'Feb - registro gastos'!$E$3:$E$300,Feb!$H$27,'Feb - registro gastos'!$F$3:$F$300,Feb!H34) -> 0 | L34: =J34-K34 -> 0
E35: =SUMIFS('Feb - registro gastos'!$D$3:$D$300,'Feb - registro gastos'!$E$3:$E$300,Feb!$B$27,'Feb - registro gastos'!$F$3:$F$300,Feb!B35) -> 0 | F35: =D35-E35 -> 0 | K35: =SUMIFS('Feb - registro gastos'!$D$3:$D$300,'Feb - registro gastos'!$E$3:$E$300,Feb!$H$27,'Feb - registro gastos'!$F$3:$F$300,Feb!H35) -> 0 | L35: =J35-K35 -> 0
B36: Subtotal | D36: =SUM(D28:D35) -> 0 | E36: =SUM(E28:E35) -> 0 | F36: =D36-E36 -> 0 | H36: Subtotal | J36: =SUM(J28:J35) -> 0 | K36: =SUM(K28:K35) -> 0 | L36: =J36-K36 -> 0
B38: CASA | C38: Ahorro | D38: Presupuesto | E38: Gasto | F38: Disponible | H38: TRANSPORTE | I38: Ahorro | J38: Presupuesto | K38: Gasto | L38: Disponible
B39: Limpieza | E39: =SUMIFS('Feb - registro gastos'!$D$3:$D$300,'Feb - registro gastos'!$E$3:$E$300,Feb!$B$38,'Feb - registro gastos'!$F$3:$F$300,Feb!B39) -> 0 | F39: =D39-E39 -> 0 | H39: Uber/taxi | K39: =SUMIFS('Feb - registro gastos'!$D$3:$D$300,'Feb - registro gastos'!$E$3:$E$300,Feb!$H$38,'Feb - registro gastos'!$F$3:$F$300,Feb!H39) -> 0 | L39: =J39-K39 -> 0
B40: Mantenimiento | E40: =SUMIFS('Feb - registro gastos'!$D$3:$D$300,'Feb - registro gastos'!$E$3:$E$300,Feb!$B$38,'Feb - registro gastos'!$F$3:$F$300,Feb!B40) -> 0 | F40: =D40-E40 -> 0 | H40: Estacionamiento | K40: =SUMIFS('Feb - registro gastos'!$D$3:$D$300,'Feb - registro gastos'!$E$3:$E$300,Feb!$H$38,'Feb - registro gastos'!$F$3:$F$300,Feb!H40) -> 0 | L40: =J40-K40 -> 0
B41: Muebles | E41: =SUMIFS('Feb - registro gastos'!$D$3:$D$300,'Feb - registro gastos'!$E$3:$E$300,Feb!$B$38,'Feb - registro gastos'!$F$3:$F$300,Feb!B41) -> 0 | F41: =D41-E41 -> 0 | H41: Mantenimiento | K41: =SUMIFS('Feb - registro gastos'!$D$3:$D$300,'Feb - registro gastos'!$E$3:$E$300,Feb!$H$38,'Feb - registro gastos'!$F$3:$F$300,Feb!H41) -> 0 | L41: =J41-K41 -> 0
B42: Impuestos | E42: =SUMIFS('Feb - registro gastos'!$D$3:$D$300,'Feb - registro gastos'!$E$3:$E$300,Feb!$B$38,'Feb - registro gastos'!$F$3:$F$300,Feb!B42) -> 0 | F42: =D42-E42 -> 0 | H42: Impuestos | K42: =SUMIFS('Feb - registro gastos'!$D$3:$D$300,'Feb - registro gastos'!$E$3:$E$300,Feb!$H$38,'Feb - registro gastos'!$F$3:$F$300,Feb!H42) -> 0 | L42: =J42-K42 -> 0
E43: =SUMIFS('Feb - registro gastos'!$D$3:$D$300,'Feb - registro gastos'!$E$3:$E$300,Feb!$B$38,'Feb - registro gastos'!$F$3:$F$300,Feb!B43) -> 0 | F43: =D43-E43 -> 0 | H43: Panapass/Peaje | K43: =SUMIFS('Feb - registro gastos'!$D$3:$D$300,'Feb - registro gastos'!$E$3:$E$300,Feb!$H$38,'Feb - registro gastos'!$F$3:$F$300,Feb!H43) -> 0 | L43: =J43-K43 -> 0
E44: =SUMIFS('Feb - registro gastos'!$D$3:$D$300,'Feb - registro gastos'!$E$3:$E$300,Feb!$B$38,'Feb - registro gastos'!$F$3:$F$300,Feb!B44) -> 0 | F44: =D44-E44 -> 0 | K44: =SUMIFS('Feb - registro gastos'!$D$3:$D$300,'Feb - registro gastos'!$E$3:$E$300,Feb!$H$38,'Feb - registro gastos'!$F$3:$F$300,Feb!H44) -> 0 | L44: =J44-K44 -> 0
E45: =SUMIFS('Feb - registro gastos'!$D$3:$D$300,'Feb - registro gastos'!$E$3:$E$300,Feb!$B$38,'Feb - registro gastos'!$F$3:$F$300,Feb!B45) -> 0 | F45: =D45-E45 -> 0 | K45: =SUMIFS('Feb - registro gastos'!$D$3:$D$300,'Feb - registro gastos'!$E$3:$E$300,Feb!$H$38,'Feb - registro gastos'!$F$3:$F$300,Feb!H45) -> 0 | L45: =J45-K45 -> 0
B46: Subtotal | D46: =SUM(D39:D45) -> 0 | E46: =SUM(E39:E45) -> 0 | F46: =D46-E46 -> 0 | H46: Subtotal | J46: =SUM(J39:J45) -> 0 | K46: =SUM(K39:K45) -> 0 | L46: =J46-K46 -> 0
B48: ALIMENTACIÓN | C48: Ahorro | D48: Presupuesto | E48: Gasto | F48: Disponible | H48: SEGUROS | I48: Ahorro | J48: Presupuesto | K48: Gasto | L48: Disponible
B49: Restaurantes | E49: =SUMIFS('Feb - registro gastos'!$D$3:$D$300,'Feb - registro gastos'!$E$3:$E$300,Feb!$B$48,'Feb - registro gastos'!$F$3:$F$300,Feb!B49) -> 0 | F49: =D49-E49 -> 0 | H49: Carro | K49: =SUMIFS('Feb - registro gastos'!$D$3:$D$300,'Feb - registro gastos'!$E$3:$E$300,Feb!$H$48,'Feb - registro gastos'!$F$3:$F$300,Feb!H49) -> 0 | L49: =J49-K49 -> 0
